<?xml version="1.0" encoding="UTF-8"?>
<testsuite name="test_failure_output" errors="1" failures="17" tests="18" time="0.082083" hostname="unknown" timestamp="2015-01-06T18:00:41">
  <properties/>
  <testcase classname="test_failure_output" name="test_empty">
    <failure>
(No failure message provided)
In C:\Users\Alexander\repositories\mlunit\sample\failure_samples\test_failure_output.m at line 13.
    </failure>
  </testcase>
  <testcase classname="test_failure_output" name="test_not_empty">
    <failure>
(No failure message provided)
In C:\Users\Alexander\repositories\mlunit\sample\failure_samples\test_failure_output.m at line 18.
    </failure>
  </testcase>
  <testcase classname="test_failure_output" name="test_false">
    <failure>
(No failure message provided)
In C:\Users\Alexander\repositories\mlunit\sample\failure_samples\test_failure_output.m at line 23.
    </failure>
  </testcase>
  <testcase classname="test_failure_output" name="test_true">
    <failure>
(No failure message provided)
In C:\Users\Alexander\repositories\mlunit\sample\failure_samples\test_failure_output.m at line 28.
    </failure>
  </testcase>
  <testcase classname="test_failure_output" name="test_fail">
    <failure>
This some custom fail message
In C:\Users\Alexander\repositories\mlunit\sample\failure_samples\test_failure_output.m at line 32.
    </failure>
  </testcase>
  <testcase classname="test_failure_output" name="test_equals">
    <failure>
Expected 3 actually was 4.
In C:\Users\Alexander\repositories\mlunit\sample\failure_samples\test_failure_output.m at line 37.
    </failure>
  </testcase>
  <testcase classname="test_failure_output" name="test_equals_array">
    <failure>
Expected [1 2 3 4 5 6 7 8 9 10 11 12 13 14 15 16] actually was [1 2 3 4 5 6 7 8 9 10.000001 11 12 13 14 15].
In C:\Users\Alexander\repositories\mlunit\sample\failure_samples\test_failure_output.m at line 43.
    </failure>
  </testcase>
  <testcase classname="test_failure_output" name="test_equals_arraymatrix">
    <failure>
Expected [1 2 3 4;5 6 7 8;9 10 11 12;13 14 15 16] actually was [1 2 3 4;5 6 7 8;9 10.000001 11 12;13 14 15 16].
In C:\Users\Alexander\repositories\mlunit\sample\failure_samples\test_failure_output.m at line 51.
    </failure>
  </testcase>
  <testcase classname="test_failure_output" name="test_equals_string">
    <failure>
Expected 'foo' actually was 'fOo'.
In C:\Users\Alexander\repositories\mlunit\sample\failure_samples\test_failure_output.m at line 56.
    </failure>
  </testcase>
  <testcase classname="test_failure_output" name="test_equals_cell">
    <failure>
Expected {3, 'foo'} actually was {3, 'fOo'}.
In C:\Users\Alexander\repositories\mlunit\sample\failure_samples\test_failure_output.m at line 63.
    </failure>
  </testcase>
  <testcase classname="test_failure_output" name="test_equals_struct">
    <failure>
Expected [{foo:{'hi', 'ho'}; bar:[3 4]}] actually was [{foo:{'ho', 'hi'}; bar:[3 4]}].
In C:\Users\Alexander\repositories\mlunit\sample\failure_samples\test_failure_output.m at line 71.
    </failure>
  </testcase>
  <testcase classname="test_failure_output" name="test_equals_structarray">
    <failure>
Expected [{foo:{'hi', 'ho'}; bar:3}, {foo:{'hi', 'ho'}; bar:4}] actually was [{foo:{'hi', 'ho'}; bar:3}, {foo:{'ho', 'hi'}; bar:4}].
In C:\Users\Alexander\repositories\mlunit\sample\failure_samples\test_failure_output.m at line 79.
    </failure>
  </testcase>
  <testcase classname="test_failure_output" name="test_not_equals">
    <failure>
Expected 3 actually was 3.
In C:\Users\Alexander\repositories\mlunit\sample\failure_samples\test_failure_output.m at line 84.
    </failure>
  </testcase>
  <testcase classname="test_failure_output" name="test_error">
    <failure>
Error expected, but none occurred.
In C:\Users\Alexander\repositories\mlunit\sample\failure_samples\test_failure_output.m at line 89.
    </failure>
  </testcase>
  <testcase classname="test_failure_output" name="test_typed_error">
    <failure>
Error expected, but none occurred.
In C:\Users\Alexander\repositories\mlunit\sample\failure_samples\test_failure_output.m at line 94.
    </failure>
  </testcase>
  <testcase classname="test_failure_output" name="test_wrong_typed_error">
    <failure>
Error occurred, but did not match criteria. Expected error identifier 'MATLAB:SomeError' actually was 'MATLAB:m_improper_grouping'.
In C:\Users\Alexander\repositories\mlunit\sample\failure_samples\test_failure_output.m at line 98.
    </failure>
  </testcase>
  <testcase classname="test_failure_output" name="test_warning">
    <failure>
No warning MATLAB:rmpath:DirNotFound when executing function @()3.
In C:\Users\Alexander\repositories\mlunit\sample\failure_samples\test_failure_output.m at line 104.
    </failure>
  </testcase>
  <testcase classname="test_failure_output" name="test_implementation_fault">
    <error>
Undefined function or variable 'unknown_function_call'.
In C:\Users\Alexander\repositories\mlunit\sample\failure_samples\test_failure_output.m at line 108
In C:\Users\Alexander\repositories\mlunit\src\@function_test_case\run_test.m at line 21
In C:\Users\Alexander\repositories\mlunit\src\@test_case\run.m at line 42
In C:\Users\Alexander\repositories\mlunit\src\@test_suite\run.m at line 24
In C:\Users\Alexander\repositories\mlunit\src\automation\recursive_test_run.m at line 84
In C:\Users\Alexander\repositories\mlunit\src\automation\recursive_test_run.m at line 41
    </error>
  </testcase>
  <system-out/>
  <system-err/>
</testsuite>
